Traceback (most recent call last):
  File "/usr/share/miniconda/envs/hatp23b/lib/python3.9/site-packages/jupyter_cache/executors/utils.py", line 51, in single_nb_execution
    executenb(
  File "/usr/share/miniconda/envs/hatp23b/lib/python3.9/site-packages/nbclient/client.py", line 1087, in execute
    return NotebookClient(nb=nb, resources=resources, km=km, **kwargs).execute()
  File "/usr/share/miniconda/envs/hatp23b/lib/python3.9/site-packages/nbclient/util.py", line 74, in wrapped
    return just_run(coro(*args, **kwargs))
  File "/usr/share/miniconda/envs/hatp23b/lib/python3.9/site-packages/nbclient/util.py", line 53, in just_run
    return loop.run_until_complete(coro)
  File "/usr/share/miniconda/envs/hatp23b/lib/python3.9/asyncio/base_events.py", line 642, in run_until_complete
    return future.result()
  File "/usr/share/miniconda/envs/hatp23b/lib/python3.9/site-packages/nbclient/client.py", line 540, in async_execute
    await self.async_execute_cell(
  File "/usr/share/miniconda/envs/hatp23b/lib/python3.9/site-packages/nbclient/client.py", line 832, in async_execute_cell
    self._check_raise_for_error(cell, exec_reply)
  File "/usr/share/miniconda/envs/hatp23b/lib/python3.9/site-packages/nbclient/client.py", line 740, in _check_raise_for_error
    raise CellExecutionError.from_cell_and_msg(cell, exec_reply['content'])
nbclient.exceptions.CellExecutionError: An error occurred while executing the following cell:
------------------
plt.hist(df_southworth["a(AU)"], bins=50, label="tepcat")
plt.xlim(-0.5, 2)
plt.xlabel("a (AU)")
plt.ylabel("count")
plt.legend(fontsize=12)

utils.savefig("/home/mango/Desktop/tepcat.png", dpi=250)
------------------

[0;31m---------------------------------------------------------------------------[0m
[0;31mFileNotFoundError[0m                         Traceback (most recent call last)
[0;32m/usr/share/miniconda/envs/hatp23b/lib/python3.9/pathlib.py[0m in [0;36mmkdir[0;34m(self, mode, parents, exist_ok)[0m
[1;32m   1311[0m         [0;32mtry[0m[0;34m:[0m[0;34m[0m[0;34m[0m[0m
[0;32m-> 1312[0;31m             [0mself[0m[0;34m.[0m[0m_accessor[0m[0;34m.[0m[0mmkdir[0m[0;34m([0m[0mself[0m[0;34m,[0m [0mmode[0m[0;34m)[0m[0;34m[0m[0;34m[0m[0m
[0m[1;32m   1313[0m         [0;32mexcept[0m [0mFileNotFoundError[0m[0;34m:[0m[0;34m[0m[0;34m[0m[0m

[0;31mFileNotFoundError[0m: [Errno 2] No such file or directory: '/home/mango/Desktop'

During handling of the above exception, another exception occurred:

[0;31mPermissionError[0m                           Traceback (most recent call last)
[0;32m<ipython-input-6-6132a66fbebb>[0m in [0;36m<module>[0;34m[0m
[1;32m      5[0m [0mplt[0m[0;34m.[0m[0mlegend[0m[0;34m([0m[0mfontsize[0m[0;34m=[0m[0;36m12[0m[0;34m)[0m[0;34m[0m[0;34m[0m[0m
[1;32m      6[0m [0;34m[0m[0m
[0;32m----> 7[0;31m [0mutils[0m[0;34m.[0m[0msavefig[0m[0;34m([0m[0;34m"/home/mango/Desktop/tepcat.png"[0m[0;34m,[0m [0mdpi[0m[0;34m=[0m[0;36m250[0m[0;34m)[0m[0;34m[0m[0;34m[0m[0m
[0m
[0;32m~/work/HAT-P-23b/HAT-P-23b/notebooks/utils.py[0m in [0;36msavefig[0;34m(fpath, **kwargs)[0m
[1;32m   1052[0m [0;34m[0m[0m
[1;32m   1053[0m [0;32mdef[0m [0msavefig[0m[0;34m([0m[0mfpath[0m[0;34m,[0m [0;34m**[0m[0mkwargs[0m[0;34m)[0m[0;34m:[0m[0;34m[0m[0;34m[0m[0m
[0;32m-> 1054[0;31m     [0mpathlib[0m[0;34m.[0m[0mPath[0m[0;34m([0m[0mfpath[0m[0;34m)[0m[0;34m.[0m[0mparents[0m[0;34m[[0m[0;36m0[0m[0;34m][0m[0;34m.[0m[0mmkdir[0m[0;34m([0m[0mparents[0m[0;34m=[0m[0;32mTrue[0m[0;34m,[0m [0mexist_ok[0m[0;34m=[0m[0;32mTrue[0m[0;34m)[0m[0;34m[0m[0;34m[0m[0m
[0m[1;32m   1055[0m     [0mplt[0m[0;34m.[0m[0msavefig[0m[0;34m([0m[0mfpath[0m[0;34m,[0m [0mbbox_inches[0m[0;34m=[0m[0;34m"tight"[0m[0;34m,[0m [0;34m**[0m[0mkwargs[0m[0;34m)[0m[0;34m[0m[0;34m[0m[0m
[1;32m   1056[0m [0;34m[0m[0m

[0;32m/usr/share/miniconda/envs/hatp23b/lib/python3.9/pathlib.py[0m in [0;36mmkdir[0;34m(self, mode, parents, exist_ok)[0m
[1;32m   1314[0m             [0;32mif[0m [0;32mnot[0m [0mparents[0m [0;32mor[0m [0mself[0m[0;34m.[0m[0mparent[0m [0;34m==[0m [0mself[0m[0;34m:[0m[0;34m[0m[0;34m[0m[0m
[1;32m   1315[0m                 [0;32mraise[0m[0;34m[0m[0;34m[0m[0m
[0;32m-> 1316[0;31m             [0mself[0m[0;34m.[0m[0mparent[0m[0;34m.[0m[0mmkdir[0m[0;34m([0m[0mparents[0m[0;34m=[0m[0;32mTrue[0m[0;34m,[0m [0mexist_ok[0m[0;34m=[0m[0;32mTrue[0m[0;34m)[0m[0;34m[0m[0;34m[0m[0m
[0m[1;32m   1317[0m             [0mself[0m[0;34m.[0m[0mmkdir[0m[0;34m([0m[0mmode[0m[0;34m,[0m [0mparents[0m[0;34m=[0m[0;32mFalse[0m[0;34m,[0m [0mexist_ok[0m[0;34m=[0m[0mexist_ok[0m[0;34m)[0m[0;34m[0m[0;34m[0m[0m
[1;32m   1318[0m         [0;32mexcept[0m [0mOSError[0m[0;34m:[0m[0;34m[0m[0;34m[0m[0m

[0;32m/usr/share/miniconda/envs/hatp23b/lib/python3.9/pathlib.py[0m in [0;36mmkdir[0;34m(self, mode, parents, exist_ok)[0m
[1;32m   1310[0m         """
[1;32m   1311[0m         [0;32mtry[0m[0;34m:[0m[0;34m[0m[0;34m[0m[0m
[0;32m-> 1312[0;31m             [0mself[0m[0;34m.[0m[0m_accessor[0m[0;34m.[0m[0mmkdir[0m[0;34m([0m[0mself[0m[0;34m,[0m [0mmode[0m[0;34m)[0m[0;34m[0m[0;34m[0m[0m
[0m[1;32m   1313[0m         [0;32mexcept[0m [0mFileNotFoundError[0m[0;34m:[0m[0;34m[0m[0;34m[0m[0m
[1;32m   1314[0m             [0;32mif[0m [0;32mnot[0m [0mparents[0m [0;32mor[0m [0mself[0m[0;34m.[0m[0mparent[0m [0;34m==[0m [0mself[0m[0;34m:[0m[0;34m[0m[0;34m[0m[0m

[0;31mPermissionError[0m: [Errno 13] Permission denied: '/home/mango'
PermissionError: [Errno 13] Permission denied: '/home/mango'

